Here is the traceback from the bug that seemed to go away

In [9]: response = equest.execute()
---------------------------------------------------
NameError         Traceback (most recent call last)
Cell In[9], line 1
----> 1 response = equest.execute()

NameError: name 'equest' is not defined

In [10]: response = request.execute()
---------------------------------------------------
TypeError         Traceback (most recent call last)
Cell In[10], line 1
----> 1 response = request.execute()

File ~\OneDrive\Desktop\repos\pp4-playlist-manager\venv\Lib\site-packages\googleapiclient\_helpers.py:130, in positional.<locals>.positional_decorator.<locals>.positional_wrapper(*args, **kwargs)
    128     elif positional_parameters_enforcement == POSITIONAL_WARNING:
    129         logger.warning(message)
--> 130 return wrapped(*args, **kwargs)

File ~\OneDrive\Desktop\repos\pp4-playlist-manager\venv\Lib\site-packages\googleapiclient\http.py:923, in HttpRequest.execute(self, http, num_retries)   
    920     self.headers["content-length"] = str(len(self.body))
    922 # Handle retries for server-side errors.   
--> 923 resp, content = _retry_request(
    924     http,
    925     num_retries,
    926     "request",
    927     self._sleep,
    928     self._rand,
    929     str(self.uri),
    930     method=str(self.method),
    931     body=self.body,
    932     headers=self.headers,
    933 )
    935 for callback in self.response_callbacks:   
    936     callback(resp)

File ~\OneDrive\Desktop\repos\pp4-playlist-manager\venv\Lib\site-packages\googleapiclient\http.py:191, in _retry_request(http, num_retries, req_type, sleep, rand, uri, method, *args, **kwargs)
    189 try:
    190     exception = None
--> 191     resp, content = http.request(uri, method, *args, **kwargs)
    192 # Retry on SSL errors and socket timeout errors.
    193 except _ssl_SSLError as ssl_error:

File ~\OneDrive\Desktop\repos\pp4-playlist-manager\venv\Lib\site-packages\google_auth_httplib2.py:245, in AuthorizedHttp.request(self, uri, method, body, headers, redirections, connection_type, **kwargs) 
    233 if (
    234     response.status in self._refresh_status_codes
    235     and _credential_refresh_attempt < self._max_refresh_attempts
    236 ):
    238     _LOGGER.info(
    239         "Refreshing credentials due to a %s response. Attempt %s/%s.",
    240         response.status,
    241         _credential_refresh_attempt + 1,   
    242         self._max_refresh_attempts,        
    243     )
--> 245     self.credentials.refresh(self._request)
    247     # Restore the body's stream position if needed.
    248     if body_stream_position is not None:   

File ~\OneDrive\Desktop\repos\pp4-playlist-manager\venv\Lib\site-packages\google\oauth2\credentials.py:431, in Credentials.refresh(self, request)        
    413 if (
    414     self._refresh_token is None
    415     or self._token_uri is None
    416     or self._client_id is None
    417     or self._client_secret is None
    418 ):
    419     raise exceptions.RefreshError(
    420         "The credentials do not contain the necessary fields need to "
    421         "refresh the access token. You must specify refresh_token, "
    422         "token_uri, client_id, and client_secret."
    423     )
    425 (
    426     access_token,
    427     refresh_token,
    428     expiry,
    429     grant_response,
    430     rapt_token,
--> 431 ) = reauth.refresh_grant(
    432     request,
    433     self._token_uri,
    434     self._refresh_token,
    435     self._client_id,
    436     self._client_secret,
    437     scopes=scopes,
    438     rapt_token=self._rapt_token,
    439     enable_reauth_refresh=self._enable_reauth_refresh,                                        
    440 )
    442 self.token = access_token
    443 self.expiry = expiry

File ~\OneDrive\Desktop\repos\pp4-playlist-manager\venv\Lib\site-packages\google\oauth2\reauth.py:327, in refresh_grant(request, token_uri, refresh_token, client_id, client_secret, scopes, rapt_token, enable_reauth_refresh)
    320 body = {
    321     "grant_type": _client._REFRESH_GRANT_TYPE,
    322     "client_id": client_id,
    323     "client_secret": client_secret,        
    324     "refresh_token": refresh_token,        
    325 }
    326 if scopes:
--> 327     body["scope"] = " ".join(scopes)       
    328 if rapt_token:
    329     body["rapt"] = rapt_token

TypeError: sequence item 0: expected str instance, list found

In [11]: request = youtube.channels().list(part="s 
    ...: nippet,contentDetails",mine=True)

In [12]: response = request.execute()
---------------------------------------------------
TypeError         Traceback (most recent call last)
Cell In[12], line 1
----> 1 response = request.execute()

File ~\OneDrive\Desktop\repos\pp4-playlist-manager\venv\Lib\site-packages\googleapiclient\_helpers.py:130, in positional.<locals>.positional_decorator.<locals>.positional_wrapper(*args, **kwargs)
    128     elif positional_parameters_enforcement == POSITIONAL_WARNING:
    129         logger.warning(message)
--> 130 return wrapped(*args, **kwargs)

File ~\OneDrive\Desktop\repos\pp4-playlist-manager\venv\Lib\site-packages\googleapiclient\http.py:923, in HttpRequest.execute(self, http, num_retries)   
    920     self.headers["content-length"] = str(len(self.body))
    922 # Handle retries for server-side errors.   
--> 923 resp, content = _retry_request(
    924     http,
    925     num_retries,
    926     "request",
    927     self._sleep,
    928     self._rand,
    929     str(self.uri),
    930     method=str(self.method),
    931     body=self.body,
    932     headers=self.headers,
    933 )
    935 for callback in self.response_callbacks:   
    936     callback(resp)

File ~\OneDrive\Desktop\repos\pp4-playlist-manager\venv\Lib\site-packages\googleapiclient\http.py:191, in _retry_request(http, num_retries, req_type, sleep, rand, uri, method, *args, **kwargs)
    189 try:
    190     exception = None
--> 191     resp, content = http.request(uri, method, *args, **kwargs)
    192 # Retry on SSL errors and socket timeout errors.
    193 except _ssl_SSLError as ssl_error:

File ~\OneDrive\Desktop\repos\pp4-playlist-manager\venv\Lib\site-packages\google_auth_httplib2.py:245, in AuthorizedHttp.request(self, uri, method, body, headers, redirections, connection_type, **kwargs) 
    233 if (
    234     response.status in self._refresh_status_codes
    235     and _credential_refresh_attempt < self._max_refresh_attempts
    236 ):
    238     _LOGGER.info(
    239         "Refreshing credentials due to a %s response. Attempt %s/%s.",
    240         response.status,
    241         _credential_refresh_attempt + 1,   
    242         self._max_refresh_attempts,        
    243     )
--> 245     self.credentials.refresh(self._request)
    247     # Restore the body's stream position if needed.
    248     if body_stream_position is not None:   

File ~\OneDrive\Desktop\repos\pp4-playlist-manager\venv\Lib\site-packages\google\oauth2\credentials.py:431, in Credentials.refresh(self, request)        
    413 if (
    414     self._refresh_token is None
    415     or self._token_uri is None
    416     or self._client_id is None
    417     or self._client_secret is None
    418 ):
    419     raise exceptions.RefreshError(
    420         "The credentials do not contain the necessary fields need to "
    421         "refresh the access token. You must specify refresh_token, "
    422         "token_uri, client_id, and client_secret."
    423     )
    425 (
    426     access_token,
    427     refresh_token,
    428     expiry,
    429     grant_response,
    430     rapt_token,
--> 431 ) = reauth.refresh_grant(
    432     request,
    433     self._token_uri,
    434     self._refresh_token,
    435     self._client_id,
    436     self._client_secret,
    437     scopes=scopes,
    438     rapt_token=self._rapt_token,
    439     enable_reauth_refresh=self._enable_reauth_refresh,                                        
    440 )
    442 self.token = access_token
    443 self.expiry = expiry

File ~\OneDrive\Desktop\repos\pp4-playlist-manager\venv\Lib\site-packages\google\oauth2\reauth.py:327, in refresh_grant(request, token_uri, refresh_token, client_id, client_secret, scopes, rapt_token, enable_reauth_refresh)
    320 body = {
    321     "grant_type": _client._REFRESH_GRANT_TYPE,
    322     "client_id": client_id,
    323     "client_secret": client_secret,        
    324     "refresh_token": refresh_token,        
    325 }
    326 if scopes:
--> 327     body["scope"] = " ".join(scopes)       
    328 if rapt_token:
    329     body["rapt"] = rapt_token

TypeError: sequence item 0: expected str instance, list found


PS C:\Users\seant\OneDrive\Desktop\repos\pp4-playlist-manager> py manage.py shell
Could not find platform independent libraries <prefix>      
Python 3.12.2 (tags/v3.12.2:6abddd9, Feb  6 2024, 21:26:36) [MSC v.1937 64 bit (AMD64)]
Type 'copyright', 'credits' or 'license' for more information
IPython 8.25.0 -- An enhanced Interactive Python. Type '?' for help.

In [1]: queue.publish()
------------------------------------------------------------
NameError                  Traceback (most recent call last)
Cell In[1], line 1
----> 1 queue.publish()

NameError: name 'queue' is not defined

In [2]: %run playground.py

In [3]: queue.publish()
Out[3]: 'Queue test swap already uploadeded to youtube.'    

In [4]: queue.youtube_id = ""

In [5]: queue.save()

In [6]: queue.publish()
------------------------------------------------------------
OperationalError           Traceback (most recent call last)
File ~\OneDrive\Desktop\repos\pp4-playlist-manager\venv\Lib\site-packages\django\db\backends\utils.py:89, in CursorWrapper._execute(self, sql, params, *ignored_wrapper_args)       
     88 else:
---> 89     return self.cursor.execute(sql, params)

File ~\OneDrive\Desktop\repos\pp4-playlist-manager\venv\Lib\site-packages\django\db\backends\sqlite3\base.py:328, in SQLiteCursorWrapper.execute(self, query, params)
    327 query = self.convert_query(query, param_names=param_names)
--> 328 return super().execute(query, params)

OperationalError: no such column: queues_entry.youtube_id   

The above exception was the direct cause of the following exception:

OperationalError           Traceback (most recent call last)
Cell In[6], line 1
----> 1 queue.publish()

File ~\OneDrive\Desktop\repos\pp4-playlist-manager\queues\models.py:59, in Queue.publish(self)
     57 youtube_id = yt.create_playlist(title=self.name, description=self.description)
     58 self.youtube_id = youtube_id
---> 59 for entry in self.entries.all():
     60     entry.publish(yt, youtube_id)
     61 self.synced = True

File ~\OneDrive\Desktop\repos\pp4-playlist-manager\venv\Lib\site-packages\django\db\models\query.py:398, in QuerySet.__iter__(self)
    383 def __iter__(self):
    384     """
    385     The queryset iterator protocol uses three nested iterators in the
    386     default case:
   (...)
    396            - Responsible for turning the rows into model objects.
    397     """
--> 398     self._fetch_all()
    399     return iter(self._result_cache)

File ~\OneDrive\Desktop\repos\pp4-playlist-manager\venv\Lib\site-packages\django\db\models\query.py:1881, in QuerySet._fetch_all(self)
   1879 def _fetch_all(self):
   1880     if self._result_cache is None:
-> 1881         self._result_cache = list(self._iterable_class(self))
   1882     if self._prefetch_related_lookups and not self._prefetch_done:
   1883         self._prefetch_related_objects()

File ~\OneDrive\Desktop\repos\pp4-playlist-manager\venv\Lib\site-packages\django\db\models\query.py:91, in ModelIterable.__iter__(self)
     88 compiler = queryset.query.get_compiler(using=db)    
     89 # Execute the query. This will also fill compiler.select, klass_info,
     90 # and annotations.
---> 91 results = compiler.execute_sql(
     92     chunked_fetch=self.chunked_fetch, chunk_size=self.chunk_size
     93 )
     94 select, klass_info, annotation_col_map = (
     95     compiler.select,
     96     compiler.klass_info,
     97     compiler.annotation_col_map,
     98 )
     99 model_cls = klass_info["model"]

File ~\OneDrive\Desktop\repos\pp4-playlist-manager\venv\Lib\site-packages\django\db\models\sql\compiler.py:1562, in SQLCompiler.execute_sql(self, result_type, chunked_fetch, chunk_size)
   1560     cursor = self.connection.cursor()
   1561 try:
-> 1562     cursor.execute(sql, params)
   1563 except Exception:
   1564     # Might fail for server-side cursors (e.g. connection closed)
   1565     cursor.close()

File ~\OneDrive\Desktop\repos\pp4-playlist-manager\venv\Lib\site-packages\django\db\backends\utils.py:102, in CursorDebugWrapper.execute(self, sql, params)
    100 def execute(self, sql, params=None):
    101     with self.debug_sql(sql, params, use_last_executed_query=True):
--> 102         return super().execute(sql, params)

File ~\OneDrive\Desktop\repos\pp4-playlist-manager\venv\Lib\site-packages\django\db\backends\utils.py:67, in CursorWrapper.execute(self, sql, params)
     66 def execute(self, sql, params=None):
---> 67     return self._execute_with_wrappers(
     68         sql, params, many=False, executor=self._execute                                                         
     69     )

File ~\OneDrive\Desktop\repos\pp4-playlist-manager\venv\Lib\site-packages\django\db\backends\utils.py:80, in CursorWrapper._execute_with_wrappers(self, sql, params, many, executor)
     78 for wrapper in reversed(self.db.execute_wrappers):  
     79     executor = functools.partial(wrapper, executor) 
---> 80 return executor(sql, params, many, context)

File ~\OneDrive\Desktop\repos\pp4-playlist-manager\venv\Lib\site-packages\django\db\backends\utils.py:84, in CursorWrapper._execute(self, sql, params, *ignored_wrapper_args)       
     82 def _execute(self, sql, params, *ignored_wrapper_args):
     83     self.db.validate_no_broken_transaction()        
---> 84     with self.db.wrap_database_errors:
     85         if params is None:
     86             # params default might be backend specific.
     87             return self.cursor.execute(sql)

File ~\OneDrive\Desktop\repos\pp4-playlist-manager\venv\Lib\site-packages\django\db\utils.py:91, in DatabaseErrorWrapper.__exit__(self, exc_type, exc_value, traceback)
     89 if dj_exc_type not in (DataError, IntegrityError):  
     90     self.wrapper.errors_occurred = True
---> 91 raise dj_exc_value.with_traceback(traceback) from exc_value

File ~\OneDrive\Desktop\repos\pp4-playlist-manager\venv\Lib\site-packages\django\db\backends\utils.py:89, in CursorWrapper._execute(self, sql, params, *ignored_wrapper_args)       
     87     return self.cursor.execute(sql)
     88 else:
---> 89     return self.cursor.execute(sql, params)

File ~\OneDrive\Desktop\repos\pp4-playlist-manager\venv\Lib\site-packages\django\db\backends\sqlite3\base.py:328, in SQLiteCursorWrapper.execute(self, query, params)
    326 param_names = list(params) if isinstance(params, Mapping) else None
    327 query = self.convert_query(query, param_names=param_names)
--> 328 return super().execute(query, params)

OperationalError: no such column: queues_entry.youtube_i

https://pp4-playlist-manager-67004a99f0e2.herokuapp.com/queues/gain_access/X86UrJsH6QB7io5WHCjd/aY2vevAgwEcQQ455jnoZ



Error from Tarek:
Environment:


Request Method: GET
Request URL: https://pp4-playlist-manager-67004a99f0e2.herokuapp.com/?state=VEpnOWMzwU28IcjohHXbUtJsIuRIQL&code=4/0ATx3LY73fqfHdwU-3_99_qliyQfJ2fWMDqLvpn3YV5bBYei6XWg-3I9VLgdmVP_TRVLHKA&scope=https://www.googleapis.com/auth/youtube

Django Version: 4.2.13
Python Version: 3.12.3
Installed Applications:
['django.contrib.admin',
 'django.contrib.auth',
 'django.contrib.contenttypes',
 'django.contrib.sessions',
 'django.contrib.messages',
 'django.contrib.staticfiles',
 'django.contrib.sites',
 'allauth',
 'allauth.account',
 'allauth.socialaccount',
 'profiles',
 'yt_auth',
 'yt_query',
 'queues']
Installed Middleware:
['django.middleware.security.SecurityMiddleware',
 'django.contrib.sessions.middleware.SessionMiddleware',
 'django.middleware.common.CommonMiddleware',
 'django.contrib.sessions.middleware.SessionMiddleware',
 'django.middleware.csrf.CsrfViewMiddleware',
 'django.contrib.auth.middleware.AuthenticationMiddleware',
 'django.contrib.messages.middleware.MessageMiddleware',
 'django.middleware.clickjacking.XFrameOptionsMiddleware',
 'allauth.account.middleware.AccountMiddleware']



Traceback (most recent call last):
  File "/app/.heroku/python/lib/python3.12/site-packages/django/core/handlers/exception.py", line 55, in inner
    response = get_response(request)
               ^^^^^^^^^^^^^^^^^^^^^
  File "/app/.heroku/python/lib/python3.12/site-packages/django/core/handlers/base.py", line 197, in _get_response
    response = wrapped_callback(request, *callback_args, **callback_kwargs)
               ^^^^^^^^^^^^^^^^^^^^^^^^^^^^^^^^^^^^^^^^^^^^^^^^^^^^^^^^^^^^
  File "/app/profiles/views.py", line 23, in index
    return return_from_authorization(request)
           ^^^^^^^^^^^^^^^^^^^^^^^^^^^^^^^^^^
  File "/app/profiles/views.py", line 92, in return_from_authorization
    msg = user.set_credentials(tokens)
          ^^^^^^^^^^^^^^^^^^^^^^^^^^^^
  File "/app/profiles/models.py", line 155, in set_credentials
    self.find_youtube_data()
    ^^^^^^^^^^^^^^^^^^^^^^^^
  File "/app/profiles/models.py", line 163, in find_youtube_data
    self.youtube_id, self.youtube_handle = yt.find_user_youtube_data()
                                           ^^^^^^^^^^^^^^^^^^^^^^^^^^^
  File "/app/yt_query/yt_api_utils.py", line 31, in find_user_youtube_data
    return parse_channel_result(response)
           ^^^^^^^^^^^^^^^^^^^^^^^^^^^^^^
  File "/app/yt_query/yt_api_utils.py", line 147, in parse_channel_result
    items = response["items"][0]
            ^^^^^^^^^^^^^^^^^

Exception Type: KeyError at /
Exception Value: 'items'

ValueError at /
The view profiles.views.index didn't return an HttpResponse object. It returned None instead.
Request Method:	GET
Request URL:	https://pp4-playlist-manager-67004a99f0e2.herokuapp.com/?state=zgXtfb1iEPPNqPyCDglUddWPypwyN8&code=4/0ATx3LY44uGUdoV25U9Y5TJvJqwWeVISEaKC-aPmlx51Ok0NTk-2BIdbPwczNnyouKT0jjA&scope=https://www.googleapis.com/auth/youtube
Django Version:	4.2.13
Exception Type:	ValueError
Exception Value:	
The view profiles.views.index didn't return an HttpResponse object. It returned None instead.
Exception Location:	/app/.heroku/python/lib/python3.12/site-packages/django/core/handlers/base.py, line 332, in check_response
Raised during:	profiles.views.index
Python Executable:	/app/.heroku/python/bin/python
Python Version:	3.12.3
Python Path:	
['/app/.heroku/python/bin',
 '/app',
 '/app/.heroku/python/lib/python312.zip',
 '/app/.heroku/python/lib/python3.12',
 '/app/.heroku/python/lib/python3.12/lib-dynload',
 '/app/.heroku/python/lib/python3.12/site-packages']
Server time:	Thu, 20 Jun 2024 15:42:57 +0000
Traceback Switch back to interactive view
Environment:


Request Method: GET
Request URL: https://pp4-playlist-manager-67004a99f0e2.herokuapp.com/?state=zgXtfb1iEPPNqPyCDglUddWPypwyN8&code=4/0ATx3LY44uGUdoV25U9Y5TJvJqwWeVISEaKC-aPmlx51Ok0NTk-2BIdbPwczNnyouKT0jjA&scope=https://www.googleapis.com/auth/youtube

Django Version: 4.2.13
Python Version: 3.12.3
Installed Applications:
['django.contrib.admin',
 'django.contrib.auth',
 'django.contrib.contenttypes',
 'django.contrib.sessions',
 'django.contrib.messages',
 'django.contrib.staticfiles',
 'django.contrib.sites',
 'corsheaders',
 'allauth',
 'allauth.account',
 'allauth.socialaccount',
 'crispy_forms',
 'crispy_bootstrap5',
 'profiles',
 'errors',
 'yt_auth',
 'yt_query',
 'queues']
Installed Middleware:
['django.middleware.security.SecurityMiddleware',
 'whitenoise.middleware.WhiteNoiseMiddleware',
 'django.contrib.sessions.middleware.SessionMiddleware',
 'corsheaders.middleware.CorsMiddleware',
 'django.middleware.common.CommonMiddleware',
 'django.middleware.csrf.CsrfViewMiddleware',
 'django.contrib.auth.middleware.AuthenticationMiddleware',
 'django.contrib.messages.middleware.MessageMiddleware',
 'django.middleware.clickjacking.XFrameOptionsMiddleware',
 'allauth.account.middleware.AccountMiddleware']



Traceback (most recent call last):
  File "/app/.heroku/python/lib/python3.12/site-packages/django/core/handlers/exception.py", line 55, in inner
    response = get_response(request)
               ^^^^^^^^^^^^^^^^^^^^^
  File "/app/.heroku/python/lib/python3.12/site-packages/django/core/handlers/base.py", line 204, in _get_response
    self.check_response(response, callback)
    ^^^^^^^^^^^^^^^^^^^^^^^^^^^^^^^^^^^^^^^
  File "/app/.heroku/python/lib/python3.12/site-packages/django/core/handlers/base.py", line 332, in check_response
    raise ValueError(
    ^

Exception Type: ValueError at /
Exception Value: The view profiles.views.index didn't return an HttpResponse object. It returned None instead.



Request information
USER
francis@francis.com

GET
Variable	Value
state	
'zgXtfb1iEPPNqPyCDglUddWPypwyN8'
code	
'4/0ATx3LY44uGUdoV25U9Y5TJvJqwWeVISEaKC-aPmlx51Ok0NTk-2BIdbPwczNnyouKT0jjA'
scope	
'https://www.googleapis.com/auth/youtube'
POST
No POST data

FILES
No FILES data

COOKIES
Variable	Value
csrftoken	
'********************'
sessionid	
'********************'
META
Variable	Value
CSRF_COOKIE	
'wCNP8RZHGdkDNUkoM1xWsW5AurvEp67X'
HTTP_ACCEPT	
'text/html,application/xhtml+xml,application/xml;q=0.9,image/avif,image/webp,image/apng,*/*;q=0.8,application/signed-exchange;v=b3;q=0.7'
HTTP_ACCEPT_ENCODING	
'gzip, deflate, br, zstd'
HTTP_ACCEPT_LANGUAGE	
'en-US,en;q=0.9,de-DE;q=0.8,de;q=0.7,en-GB;q=0.6'
HTTP_CONNECTION	
'close'
HTTP_CONNECT_TIME	
'0'
HTTP_COOKIE	
'********************'
HTTP_HOST	
'pp4-playlist-manager-67004a99f0e2.herokuapp.com'
HTTP_REFERER	
'https://accounts.google.com/'
HTTP_SEC_CH_UA	
'"Not/A)Brand";v="8", "Chromium";v="126", "Google Chrome";v="126"'
HTTP_SEC_CH_UA_MOBILE	
'?0'
HTTP_SEC_CH_UA_PLATFORM	
'"Windows"'
HTTP_SEC_FETCH_DEST	
'document'
HTTP_SEC_FETCH_MODE	
'navigate'
HTTP_SEC_FETCH_SITE	
'cross-site'
HTTP_SEC_FETCH_USER	
'?1'
HTTP_TOTAL_ROUTE_TIME	
'0'
HTTP_UPGRADE_INSECURE_REQUESTS	
'1'
HTTP_USER_AGENT	
('Mozilla/5.0 (Windows NT 10.0; Win64; x64) AppleWebKit/537.36 (KHTML, like '
 'Gecko) Chrome/126.0.0.0 Safari/537.36')
HTTP_VIA	
'1.1 vegur'
HTTP_X_FORWARDED_FOR	
'77.10.67.89'
HTTP_X_FORWARDED_PORT	
'443'
HTTP_X_FORWARDED_PROTO	
'https'
HTTP_X_REQUEST_ID	
'4c507528-e03d-4526-9689-6271a4c2e19e'
HTTP_X_REQUEST_START	
'1718898176847'
PATH_INFO	
'/'
QUERY_STRING	
'state=zgXtfb1iEPPNqPyCDglUddWPypwyN8&code=4/0ATx3LY44uGUdoV25U9Y5TJvJqwWeVISEaKC-aPmlx51Ok0NTk-2BIdbPwczNnyouKT0jjA&scope=https://www.googleapis.com/auth/youtube'
RAW_URI	
'/?state=zgXtfb1iEPPNqPyCDglUddWPypwyN8&code=4/0ATx3LY44uGUdoV25U9Y5TJvJqwWeVISEaKC-aPmlx51Ok0NTk-2BIdbPwczNnyouKT0jjA&scope=https://www.googleapis.com/auth/youtube'
REMOTE_ADDR	
'10.1.25.118'
REMOTE_PORT	
'22695'
REQUEST_METHOD	
'GET'
SCRIPT_NAME	
''
SERVER_NAME	
'0.0.0.0'
SERVER_PORT	
'29202'
SERVER_PROTOCOL	
'HTTP/1.1'
SERVER_SOFTWARE	
'gunicorn/20.1.0'
gunicorn.socket	
<socket.socket fd=10, family=2, type=1, proto=0, laddr=('172.18.70.14', 29202), raddr=('10.1.25.118', 22695)>
wsgi.errors	
<gunicorn.http.wsgi.WSGIErrorsWrapper object at 0x7f8205e98c70>
wsgi.file_wrapper	
<class 'gunicorn.http.wsgi.FileWrapper'>
wsgi.input	
<gunicorn.http.body.Body object at 0x7f8205a97d40>
wsgi.input_terminated	
True
wsgi.multiprocess	
True
wsgi.multithread	
False
wsgi.run_once	
False
wsgi.url_scheme	
'https'
wsgi.version	
(1, 0)
Settings
Using settings module pp4_youtube_dj.settings
Setting	Value
ABSOLUTE_URL_OVERRIDES	
{}
ACCOUNT_AUTHENTICATION_METHOD	
'email'
ACCOUNT_EMAIL_REQUIRED	
True
ACCOUNT_EMAIL_VERIFICATION	
'none'
ACCOUNT_USERNAME_REQUIRED	
False
ACCOUNT_USER_MODEL_USERNAME_FIELD	
None
ADMINS	
[]
ALLOWED_HOSTS	
['8000-smtilson-pp4playlistman-ym3t1koq57f.ws.codeinstitute-ide.net',
 'localhost',
 '127.0.0.1',
 '.herokuapp.com']
APPEND_SLASH	
True
AUTHENTICATION_BACKENDS	
['django.contrib.auth.backends.ModelBackend',
 'allauth.account.auth_backends.AuthenticationBackend']
AUTH_PASSWORD_VALIDATORS	
'********************'
AUTH_USER_MODEL	
'profiles.Profile'
BASE_DIR	
PosixPath('/app')
CACHES	
{'default': {'BACKEND': 'django.core.cache.backends.locmem.LocMemCache'}}
CACHE_MIDDLEWARE_ALIAS	
'default'
CACHE_MIDDLEWARE_KEY_PREFIX	
'********************'
CACHE_MIDDLEWARE_SECONDS	
600
CORS_ALLOW_HEADERS	
['*']
CORS_ORIGIN_WHITELIST	
['http://127.0.0.1:8000',
 'http://localhost:8000',
 'https://pp4-playlist-manager-67004a99f0e2.herokuapp.com']
CRISPY_ALLOWED_TEMPLATE_PACKS	
'bootstrap5'
CRISPY_TEMPLATE_PACK	
'bootstrap5'
CSRF_COOKIE_AGE	
31449600
CSRF_COOKIE_DOMAIN	
None
CSRF_COOKIE_HTTPONLY	
False
CSRF_COOKIE_MASKED	
False
CSRF_COOKIE_NAME	
'csrftoken'
CSRF_COOKIE_PATH	
'/'
CSRF_COOKIE_SAMESITE	
'Lax'
CSRF_COOKIE_SECURE	
False
CSRF_FAILURE_VIEW	
'django.views.csrf.csrf_failure'
CSRF_HEADER_NAME	
'HTTP_X_CSRFTOKEN'
CSRF_TRUSTED_ORIGINS	
['https://8000-smtilson-pp4playlistman-ym3t1koq57f.ws.codeinstitute-ide.net',
 'https://*.herokuapp.com',
 'http://*.127.0.0.1:8000',
 'http://localhost:8000',
 'https://pp4-playlist-manager-67004a99f0e2.herokuapp.com/']
CSRF_USE_SESSIONS	
False
DATABASES	
{'default': {'ATOMIC_REQUESTS': False,
             'AUTOCOMMIT': True,
             'CONN_HEALTH_CHECKS': False,
             'CONN_MAX_AGE': 0,
             'ENGINE': 'django.db.backends.sqlite3',
             'HOST': '',
             'NAME': PosixPath('/app/db.sqlite3'),
             'OPTIONS': {},
             'PASSWORD': '********************',
             'PORT': '',
             'TEST': {'CHARSET': None,
                      'COLLATION': None,
                      'MIGRATE': True,
                      'MIRROR': None,
                      'NAME': None},
             'TIME_ZONE': None,
             'USER': ''}}
DATABASE_ROUTERS	
[]
DATA_UPLOAD_MAX_MEMORY_SIZE	
2621440
DATA_UPLOAD_MAX_NUMBER_FIELDS	
1000
DATA_UPLOAD_MAX_NUMBER_FILES	
100
DATETIME_FORMAT	
'N j, Y, P'
DATETIME_INPUT_FORMATS	
['%Y-%m-%d %H:%M:%S',
 '%Y-%m-%d %H:%M:%S.%f',
 '%Y-%m-%d %H:%M',
 '%m/%d/%Y %H:%M:%S',
 '%m/%d/%Y %H:%M:%S.%f',
 '%m/%d/%Y %H:%M',
 '%m/%d/%y %H:%M:%S',
 '%m/%d/%y %H:%M:%S.%f',
 '%m/%d/%y %H:%M']
DATE_FORMAT	
'N j, Y'
DATE_INPUT_FORMATS	
['%Y-%m-%d',
 '%m/%d/%Y',
 '%m/%d/%y',
 '%b %d %Y',
 '%b %d, %Y',
 '%d %b %Y',
 '%d %b, %Y',
 '%B %d %Y',
 '%B %d, %Y',
 '%d %B %Y',
 '%d %B, %Y']
DEBUG	
True
DEBUG_PROPAGATE_EXCEPTIONS	
False
DECIMAL_SEPARATOR	
'.'
DEFAULT_AUTO_FIELD	
'django.db.models.BigAutoField'
DEFAULT_CHARSET	
'utf-8'
DEFAULT_EXCEPTION_REPORTER	
'django.views.debug.ExceptionReporter'
DEFAULT_EXCEPTION_REPORTER_FILTER	
'django.views.debug.SafeExceptionReporterFilter'
DEFAULT_FILE_STORAGE	
'django.core.files.storage.FileSystemStorage'
DEFAULT_FROM_EMAIL	
'webmaster@localhost'
DEFAULT_INDEX_TABLESPACE	
''
DEFAULT_TABLESPACE	
''
DISALLOWED_USER_AGENTS	
[]
EMAIL_BACKEND	
'django.core.mail.backends.smtp.EmailBackend'
EMAIL_HOST	
'localhost'
EMAIL_HOST_PASSWORD	
'********************'
EMAIL_HOST_USER	
''
EMAIL_PORT	
25
EMAIL_SSL_CERTFILE	
None
EMAIL_SSL_KEYFILE	
'********************'
EMAIL_SUBJECT_PREFIX	
'[Django] '
EMAIL_TIMEOUT	
None
EMAIL_USE_LOCALTIME	
False
EMAIL_USE_SSL	
False
EMAIL_USE_TLS	
False
FILE_UPLOAD_DIRECTORY_PERMISSIONS	
None
FILE_UPLOAD_HANDLERS	
['django.core.files.uploadhandler.MemoryFileUploadHandler',
 'django.core.files.uploadhandler.TemporaryFileUploadHandler']
FILE_UPLOAD_MAX_MEMORY_SIZE	
2621440
FILE_UPLOAD_PERMISSIONS	
420
FILE_UPLOAD_TEMP_DIR	
None
FIRST_DAY_OF_WEEK	
0
FIXTURE_DIRS	
[]
FORCE_SCRIPT_NAME	
None
FORMAT_MODULE_PATH	
None
FORM_RENDERER	
'django.forms.renderers.DjangoTemplates'
IGNORABLE_404_URLS	
[]
INSTALLED_APPS	
['django.contrib.admin',
 'django.contrib.auth',
 'django.contrib.contenttypes',
 'django.contrib.sessions',
 'django.contrib.messages',
 'django.contrib.staticfiles',
 'django.contrib.sites',
 'corsheaders',
 'allauth',
 'allauth.account',
 'allauth.socialaccount',
 'crispy_forms',
 'crispy_bootstrap5',
 'profiles',
 'errors',
 'yt_auth',
 'yt_query',
 'queues']
INTERNAL_IPS	
[]
LANGUAGES	
[('af', 'Afrikaans'),
 ('ar', 'Arabic'),
 ('ar-dz', 'Algerian Arabic'),
 ('ast', 'Asturian'),
 ('az', 'Azerbaijani'),
 ('bg', 'Bulgarian'),
 ('be', 'Belarusian'),
 ('bn', 'Bengali'),
 ('br', 'Breton'),
 ('bs', 'Bosnian'),
 ('ca', 'Catalan'),
 ('ckb', 'Central Kurdish (Sorani)'),
 ('cs', 'Czech'),
 ('cy', 'Welsh'),
 ('da', 'Danish'),
 ('de', 'German'),
 ('dsb', 'Lower Sorbian'),
 ('el', 'Greek'),
 ('en', 'English'),
 ('en-au', 'Australian English'),
 ('en-gb', 'British English'),
 ('eo', 'Esperanto'),
 ('es', 'Spanish'),
 ('es-ar', 'Argentinian Spanish'),
 ('es-co', 'Colombian Spanish'),
 ('es-mx', 'Mexican Spanish'),
 ('es-ni', 'Nicaraguan Spanish'),
 ('es-ve', 'Venezuelan Spanish'),
 ('et', 'Estonian'),
 ('eu', 'Basque'),
 ('fa', 'Persian'),
 ('fi', 'Finnish'),
 ('fr', 'French'),
 ('fy', 'Frisian'),
 ('ga', 'Irish'),
 ('gd', 'Scottish Gaelic'),
 ('gl', 'Galician'),
 ('he', 'Hebrew'),
 ('hi', 'Hindi'),
 ('hr', 'Croatian'),
 ('hsb', 'Upper Sorbian'),
 ('hu', 'Hungarian'),
 ('hy', 'Armenian'),
 ('ia', 'Interlingua'),
 ('id', 'Indonesian'),
 ('ig', 'Igbo'),
 ('io', 'Ido'),
 ('is', 'Icelandic'),
 ('it', 'Italian'),
 ('ja', 'Japanese'),
 ('ka', 'Georgian'),
 ('kab', 'Kabyle'),
 ('kk', 'Kazakh'),
 ('km', 'Khmer'),
 ('kn', 'Kannada'),
 ('ko', 'Korean'),
 ('ky', 'Kyrgyz'),
 ('lb', 'Luxembourgish'),
 ('lt', 'Lithuanian'),
 ('lv', 'Latvian'),
 ('mk', 'Macedonian'),
 ('ml', 'Malayalam'),
 ('mn', 'Mongolian'),
 ('mr', 'Marathi'),
 ('ms', 'Malay'),
 ('my', 'Burmese'),
 ('nb', 'Norwegian Bokmål'),
 ('ne', 'Nepali'),
 ('nl', 'Dutch'),
 ('nn', 'Norwegian Nynorsk'),
 ('os', 'Ossetic'),
 ('pa', 'Punjabi'),
 ('pl', 'Polish'),
 ('pt', 'Portuguese'),
 ('pt-br', 'Brazilian Portuguese'),
 ('ro', 'Romanian'),
 ('ru', 'Russian'),
 ('sk', 'Slovak'),
 ('sl', 'Slovenian'),
 ('sq', 'Albanian'),
 ('sr', 'Serbian'),
 ('sr-latn', 'Serbian Latin'),
 ('sv', 'Swedish'),
 ('sw', 'Swahili'),
 ('ta', 'Tamil'),
 ('te', 'Telugu'),
 ('tg', 'Tajik'),
 ('th', 'Thai'),
 ('tk', 'Turkmen'),
 ('tr', 'Turkish'),
 ('tt', 'Tatar'),
 ('udm', 'Udmurt'),
 ('uk', 'Ukrainian'),
 ('ur', 'Urdu'),
 ('uz', 'Uzbek'),
 ('vi', 'Vietnamese'),
 ('zh-hans', 'Simplified Chinese'),
 ('zh-hant', 'Traditional Chinese')]
LANGUAGES_BIDI	
['he', 'ar', 'ar-dz', 'ckb', 'fa', 'ur']
LANGUAGE_CODE	
'en-us'
LANGUAGE_COOKIE_AGE	
None
LANGUAGE_COOKIE_DOMAIN	
None
LANGUAGE_COOKIE_HTTPONLY	
False
LANGUAGE_COOKIE_NAME	
'django_language'
LANGUAGE_COOKIE_PATH	
'/'
LANGUAGE_COOKIE_SAMESITE	
None
LANGUAGE_COOKIE_SECURE	
False
LOCAL	
'False'
LOCALE_PATHS	
[]
LOGGING	
{}
LOGGING_CONFIG	
'logging.config.dictConfig'
LOGIN_REDIRECT_URL	
'/'
LOGIN_URL	
'/accounts/login/'
LOGOUT_REDIRECT_URL	
'/'
MANAGERS	
[]
MEDIA_ROOT	
''
MEDIA_URL	
'/'
MESSAGE_STORAGE	
'django.contrib.messages.storage.fallback.FallbackStorage'
MESSAGE_TAGS	
{25: 'alert-success', 40: 'alert-danger'}
MIDDLEWARE	
['django.middleware.security.SecurityMiddleware',
 'whitenoise.middleware.WhiteNoiseMiddleware',
 'django.contrib.sessions.middleware.SessionMiddleware',
 'corsheaders.middleware.CorsMiddleware',
 'django.middleware.common.CommonMiddleware',
 'django.middleware.csrf.CsrfViewMiddleware',
 'django.contrib.auth.middleware.AuthenticationMiddleware',
 'django.contrib.messages.middleware.MessageMiddleware',
 'django.middleware.clickjacking.XFrameOptionsMiddleware',
 'allauth.account.middleware.AccountMiddleware']
MIGRATION_MODULES	
{}
MONTH_DAY_FORMAT	
'F j'
NUMBER_GROUPING	
0
PASSWORD_HASHERS	
'********************'
PASSWORD_RESET_TIMEOUT	
'********************'
PREPEND_WWW	
False
ROOT_URLCONF	
'pp4_youtube_dj.urls'
SECRET_KEY	
'********************'
SECRET_KEY_FALLBACKS	
'********************'
SECURE_CONTENT_TYPE_NOSNIFF	
True
SECURE_CROSS_ORIGIN_OPENER_POLICY	
'same-origin'
SECURE_HSTS_INCLUDE_SUBDOMAINS	
False
SECURE_HSTS_PRELOAD	
False
SECURE_HSTS_SECONDS	
0
SECURE_PROXY_SSL_HEADER	
None
SECURE_REDIRECT_EXEMPT	
[]
SECURE_REFERRER_POLICY	
'same-origin'
SECURE_SSL_HOST	
None
SECURE_SSL_REDIRECT	
False
SERVER_EMAIL	
'root@localhost'
SESSION_CACHE_ALIAS	
'default'
SESSION_COOKIE_AGE	
1209600
SESSION_COOKIE_DOMAIN	
None
SESSION_COOKIE_HTTPONLY	
True
SESSION_COOKIE_NAME	
'sessionid'
SESSION_COOKIE_PATH	
'/'
SESSION_COOKIE_SAMESITE	
'Lax'
SESSION_COOKIE_SECURE	
False
SESSION_ENGINE	
'django.contrib.sessions.backends.db'
SESSION_EXPIRE_AT_BROWSER_CLOSE	
False
SESSION_FILE_PATH	
None
SESSION_SAVE_EVERY_REQUEST	
False
SESSION_SERIALIZER	
'django.contrib.sessions.serializers.JSONSerializer'
SETTINGS_MODULE	
'pp4_youtube_dj.settings'
SHORT_DATETIME_FORMAT	
'm/d/Y P'
SHORT_DATE_FORMAT	
'm/d/Y'
SIGNING_BACKEND	
'django.core.signing.TimestampSigner'
SILENCED_SYSTEM_CHECKS	
[]
SITE_ID	
1
STATICFILES_DIRS	
['/app/static']
STATICFILES_FINDERS	
['django.contrib.staticfiles.finders.FileSystemFinder',
 'django.contrib.staticfiles.finders.AppDirectoriesFinder']
STATICFILES_STORAGE	
'django.contrib.staticfiles.storage.StaticFilesStorage'
STATIC_ROOT	
'/app/staticfiles'
STATIC_URL	
'/static/'
STORAGES	
{'default': {'BACKEND': 'django.core.files.storage.FileSystemStorage'},
 'staticfiles': {'BACKEND': 'django.contrib.staticfiles.storage.StaticFilesStorage'}}
TEMPLATES	
[{'APP_DIRS': True,
  'BACKEND': 'django.template.backends.django.DjangoTemplates',
  'DIRS': ['/app/templates'],
  'OPTIONS': {'context_processors': ['django.template.context_processors.debug',
                                     'django.template.context_processors.request',
                                     'django.contrib.auth.context_processors.auth',
                                     'django.contrib.messages.context_processors.messages']}}]
TEMPLATES_DIR	
'/app/templates'
TEST_NON_SERIALIZED_APPS	
[]
TEST_RUNNER	
'django.test.runner.DiscoverRunner'
THOUSAND_SEPARATOR	
','
TIME_FORMAT	
'P'
TIME_INPUT_FORMATS	
['%H:%M:%S', '%H:%M:%S.%f', '%H:%M']
TIME_ZONE	
'UTC'
USE_DEPRECATED_PYTZ	
False
USE_I18N	
True
USE_L10N	
True
USE_THOUSAND_SEPARATOR	
False
USE_TZ	
True
USE_X_FORWARDED_HOST	
False
USE_X_FORWARDED_PORT	
False
WSGI_APPLICATION	
'pp4_youtube_dj.wsgi.application'
X_FRAME_OPTIONS	
'DENY'
YEAR_MONTH_FORMAT	
'F Y'
You’re seeing this error because you have DEBUG = True in your Django settings file. Change that to False, and Django will display a standard page generated by the handler for this status code.